
<h1>numpy.testing.assert_raises<a class="headerlink" href="#numpy-testing-assert-raises" title="Permalink to this heading">#</a></h1>
<dl class="py function">
<dt class="sig sig-object py" id="numpy.testing.assert_raises">
<span class="sig-prename descclassname"><span class="pre">testing.</span></span><span class="sig-name descname"><span class="pre">assert_raises</span></span><span class="sig-paren">(</span><em class="sig-param"><span class="n"><span class="pre">exception_class</span></span></em>, <em class="sig-param"><span class="n"><span class="pre">callable</span></span></em>, <em class="sig-param"><span class="n"><span class="pre">*args</span></span></em>, <em class="sig-param"><span class="n"><span class="pre">**kwargs)</span> <span class="pre">assert_raises(exception_class</span></span></em><span class="sig-paren">)</span><a class="reference external" href="https://github.com/numpy/numpy/blob/v1.24.0/numpy/testing/_private/utils.py#L1355-L1381"><span class="viewcode-link"><span class="pre">[source]</span></span></a><a class="headerlink" href="#numpy.testing.assert_raises" title="Permalink to this definition">#</a></dt>
<dt class="sig sig-object py">
<span class="sig-prename descclassname"><span class="pre">testing.</span></span><span class="sig-name descname"><span class="pre">assert_raises</span></span><span class="sig-paren">(</span><em class="sig-param"><span class="n"><span class="pre">exception_class</span></span></em><span class="sig-paren">)</span> <span class="sig-return"><span class="sig-return-icon">&#x2192;</span> <span class="sig-return-typehint"><a class="reference external" href="https://docs.python.org/3/library/constants.html#None" title="(in Python v3.11)"><span class="pre">None</span></a></span></span></dt>
<dd><p>Fail unless an exception of class exception_class is thrown
by callable when invoked with arguments args and keyword
arguments kwargs. If a different type of exception is
thrown, it will not be caught, and the test case will be
deemed to have suffered an error, exactly as for an
unexpected exception.</p>
<p>Alternatively, <a class="reference internal" href="#numpy.testing.assert_raises" title="numpy.testing.assert_raises"><code class="xref py py-obj docutils literal notranslate"><span class="pre">assert_raises</span></code></a> can be used as a context manager:</p>
<div class="doctest highlight-default notranslate"><div class="highlight"><pre><span></span><span class="gp">&gt;&gt;&gt; </span><span class="kn">from</span> <span class="nn">numpy.testing</span> <span class="kn">import</span> <span class="n">assert_raises</span>
<span class="gp">&gt;&gt;&gt; </span><span class="k">with</span> <span class="n">assert_raises</span><span class="p">(</span><span class="ne">ZeroDivisionError</span><span class="p">):</span>
<span class="gp">... </span>    <span class="mi">1</span> <span class="o">/</span> <span class="mi">0</span>
</pre></div>
</div>
<p>is equivalent to</p>
<div class="doctest highlight-default notranslate"><div class="highlight"><pre><span></span><span class="gp">&gt;&gt;&gt; </span><span class="k">def</span> <span class="nf">div</span><span class="p">(</span><span class="n">x</span><span class="p">,</span> <span class="n">y</span><span class="p">):</span>
<span class="gp">... </span>    <span class="k">return</span> <span class="n">x</span> <span class="o">/</span> <span class="n">y</span>
<span class="gp">&gt;&gt;&gt; </span><span class="n">assert_raises</span><span class="p">(</span><span class="ne">ZeroDivisionError</span><span class="p">,</span> <span class="n">div</span><span class="p">,</span> <span class="mi">1</span><span class="p">,</span> <span class="mi">0</span><span class="p">)</span>
</pre></div>
</div>
</dd></dl>

